Workbook

Sheet Graph
AK1: 24 | AL1: 27 | AM1: 29 | AN1: 31 | AO1: 32 | AP1: 34 | AQ1: 35 | AR1: 37 | AS1: 38 | AT1: 40 | AU1: 41 | AV1: 43 | AW1: 45 | AX1: 50 | AY1: 53 | AZ1: 56 | BA1: 62 | BB1: 78 | BC1: 94 | BD1: -1 | BE1: 0 | BF1: 4 | BG1: 5 | BH1: 6 | BI1: 12 | BJ1: 20 | BK1: 22 | BL1: 23 | BM1: 26 | BN1: 30 | BO1: 33 | BP1: 36 | BQ1: 39 | BR1: 42 | BS1: 44 | BT1: 46 | BU1: 52 | BV1: 66 | BW1: 68 | BX1: 69 | BY1: 74 | BZ1: 76 | CA1: 77 | CB1: 86 | CC1: 100 | CD1: 104 | CE1: 106 | CF1: 107 | CG1: 109 | CH1: 114 | CI1: 121 | CJ1: 123 | CK1: 124 | CL1: 125 | CM1: 127 | CN1: 131
AK2: Coprococcus eutactus ATCC 27759 | AL2: Eubacterium rectale ATCC 33656 | AM2: Tyzzerella nexilis DSM 1787 | AN2: Clostridium sp. L2-50 | AO2: Clostridium sp. M62/1 | AP2: Clostridium bolteae ATCC BAA-613 | AQ2: Clostridium hathewayi DSM 13479 | AR2: Dorea formicigenerans ATCC 27755 | AS2: Dorea longicatena DSM 13814 | AT2: Blautia hansenii DSM 20583 | AU2: Marvinbryantia formatexigens DSM 14469 (Bryantella formatexigens) | AV2: Ruminococcus torques ATCC 27756 | AW2: Subdoligranulum variabile DSM 15176 | AX2: Eubacterium ventriosum ATCC 27560 DSM 3988 | AY2: Anaerobutyricum hallii DSM 3353 (Eubacterium hallii) | AZ2: Ruminococcus lactaris ATCC 29176 | BA2: Holdemanella biformis DSM 3989 | BB2: Collinsella stercoris DSM 13279 | BC2: Solobacterium moorei DSM 22971 | BD2: Chaw | BE2: GF pellet | BF2: Bacteroides coprophilus DSM 18228 | BG2: Bacteroides dorei 5_1_36/D4 (HM 29) | BH2: Bacteroides eggerthii DSM 20697 | BI2: Bacteroides sp. 3_1_19 | BJ2: Bacteroides plebeius DSM 17135 | BK2: Bacteroides coprocola DSM 17136 | BL2: Bacteroides stercoris ATCC 43183 DSMZ 19555 | BM2: Ruminococcus gnavus ATCC 29149 | BN2: Clostridium scindens ATCC 35704 | BO2: Clostridium asparagiforme DSM 15981 | BP2: Clostridium leptum DSM 753 | BQ2: Coprococcus comes ATCC 27758 | BR2: Butyrivibrio crossotus DSM 2876 | BS2: Parabacteroides merdae DSMZ 19495 (also ATCC 43184) | BT2: Parabacteroides johnsonii DSM 18315 | BU2: Parabacteroides sp. D13 | BV2: Eubacterium siraeum DSM 15702 | BW2: Anaerostipes caccae DSM 14662 | BX2: Bacteroides cellulosilyticus DSM 14838 | BY2: Acidaminococcus fermentans DSM 20731 | BZ2: Ethanoligenens harbinense YUAN-3 DSMZ 18485 | CA2: Veillonella dispar ATCC 17748 | CB2: Veillonella sp. 6_1_27 HM 49 | CC2: Clostridium sporogenes ATCC 15579 | CD2: Ruminococcus albus strain 8 | CE2: Ruminococcus bromii ATCC | CF2: Veillonella sp. 3_1_44 HM 64 | CG2: Megasphaera DSMZ 102144 | CH2: Blautia sp. KLE 1732 (HM 1032) | CI2: Bilophila wadsworthia ATCC 49260 | CJ2: Subdoligranulum sp. 4_3_54A2FAA | CK2: Alistipes senegalensis JC50/DSM 25460 | CL2: Blautia wexlerae DSM 19850 | CM2: Intestinimonas butyriciproducens DSM 26588 | CN2: Burkholderiales bacterium 1_1_47
H8: pTreg
H9: tTreg
H10: Th1
H11: Th2
H12: Th17
H13: Fr4 Th
H14: Other Effector Th
H15: Memory
D19: TCR | E19: Community | F19: Type | G19: Tissue | H19: Total cells | I19: T cell subset | CR19: TCR | CS19: pTreg | CT19: tTreg | CU19: Th1 | CV19: Th2 | CW19: Th17 | CX19: Fr4 Th | CY19: Other Effector Th | CZ19: Memory
B20: 1 | D20: GF_6 | E20: Germ free | F20: Expanded | G20: LI | H20: 4 | AK20: 0.004721714 | AL20: 0.004721714 | AM20: 0.0094889421 | AN20: 0.0094889421 | AO20: 0.0094889421 | AP20: 0.0086331162 | AQ20: 0.018986869 | AR20: 0.037853909 | AS20: 0.004721714 | AT20: 0.010676679 | AU20: 0.004721714 | AV20: 0.004721714 | AW20: 0.0081031727 | AX20: 0.0094889421 | AY20: 0.0076758727 | AZ20: 0.004721714 | BA20: 0.004721714 | BB20: 0.00754915 | BC20: 0.017672106 | BD20: 0.0017061746 | BE20: 0.0025087334 | BF20: 0.011997676 | BG20: 0.005149014 | BH20: 0.016374803 | BI20: 0.011587275 | BJ20: 0.0094889421 | BK20: 0.012316378 | BL20: 0.014637956 | BM20: 0.00754915 | BN20: 0.0081441964 | BO20: 0.0062499184 | BP20: 0.00754915 | BQ20: 0.0094889421 | BR20: 0.018122058 | BS20: 0.004721714 | BT20: 0.012159227 | BU20: 0.0086331162 | BV20: 0.00754915 | BW20: 0.0086331162 | BX20: 0.005149014 | BY20: 0.00754915 | BZ20: 0.0086331162 | CA20: 0.009713297 | CB20: 0.0094889421 | CC20: 0.009377447 | CD20: 0.012367985 | CE20: 0.012367985 | CF20: 0.019765949 | CG20: 0.0097788878 | CH20: 0.0097788878 | CI20: 0.0059312159 | CJ20: 0.0072304474 | CK20: 0.0084796562 | CL20: 0.011997676 | CM20: 0.014546116 | CN20: 0.0072304474 | CR20: GF_6 | CS20: 3 | CT20: 1 | CU20: 0 | CV20: 0 | CW20: 0 | CX20: 0 | CY20: 0 | CZ20: 0
B21: 2 | D21: V1_33 | E21: hCom1 | F21: Expanded | G21: SI & LI | H21: 7 | AK21: 0.010956994 | AL21: 0.010956994 | AM21: 0.0077090076 | AN21: 0.0073546658 | AO21: 0.0073546658 | AP21: 0.026620938 | AQ21: 0.014175755 | AR21: 0.014798768 | AS21: 0.0073546658 | AT21: 0.010956994 | AU21: 0.010808182 | AV21: 0.0073546658 | AW21: 0.014175755 | AX21: 0.0073546658 | AY21: 0.010956994 | AZ21: 0.0073546658 | BA21: 0.0035493341 | BB21: 0 | BC21: 0.0078801822 | BD21: 1.0630623 | BE21: 0.84921555 | BF21: 0.0077090076 | BG21: 0.01561566 | BH21: 0.014431752 | BI21: 0.023616086 | BJ21: 0.014798768 | BK21: 0 | BL21: 0.010125717 | BM21: 0.0038053317 | BN21: 0.016111102 | BO21: 0.0063203857 | BP21: 0.0038053317 | BQ21: 0.0073546658 | BR21: 0.014431752 | BS21: 0.0035493341 | BT21: 0.0098697198 | BU21: 0.014175755 | BV21: 0.0015077816 | BW21: 0.017778083 | BX21: 0.01561566 | BY21: 0 | BZ21: 0.01062642 | CA21: 0.0063203857 | CB21: 0.0071516628 | CC21: 0.025816884 | CD21: 0.0039036759 | CE21: 0.0039036759 | CF21: 0.015736908 | CG21: 0.0039036759 | CH21: 0.011685514 | CI21: 0.014530096 | CJ21: 0.011685514 | CK21: 0.0080990177 | CL21: 0.0077090076 | CM21: 0.0077090076 | CN21: 0.0077090076 | CR21: V1_33 | CS21: 5 | CT21: 1 | CU21: 0 | CV21: 0 | CW21: 0 | CX21: 0 | CY21: 0 | CZ21: 1
B22: 3 | D22: V1_42 | E22: hCom1 | F22: Expanded | G22: SI & LI | H22: 7 | AK22: 0.011242123 | AL22: 0.0055808118 | AM22: 0 | AN22: 0.0055808118 | AO22: 0 | AP22: 0.011623692 | AQ22: 0.0092584812 | AR22: 0.0055808118 | AS22: 0 | AT22: 0 | AU22: 0 | AV22: 0 | AW22: 0.0069137695 | AX22: 0 | AY22: 0.0055808118 | AZ22: 0 | BA22: 0 | BB22: 0.0070885934 | BC22: 0 | BD22: 0.24937731 | BE22: 0.092759105 | BF22: 0.0055808118 | BG22: 0.0045892918 | BH22: 0.012494581 | BI22: 0.0069137695 | BJ22: 0.011242123 | BK22: 0.0070885934 | BL22: 0.012494581 | BM22: 0.0086300005 | BN22: 0.014839293 | BO22: 0.013131474 | BP22: 0.0070885934 | BQ22: 0.0055808118 | BR22: 0.014839293 | BS22: 0 | BT22: 0.0092584812 | BU22: 0.0092584812 | BV22: 0.0015077816 | BW22: 0.011623692 | BX22: 0.0069137695 | BY22: 0 | BZ22: 0.011623692 | CA22: 0.01230767 | CB22: 0 | CC22: 0.0092584812 | CD22: 0.0039565864 | CE22: 0.0095373982 | CF22: 0.0095373982 | CG22: 0.0039565864 | CH22: 0.0039565864 | CI22: 0.0045892918 | CJ22: 0.0055808118 | CK22: 0.0045892918 | CL22: 0.0095373982 | CM22: 0 | CN22: 0 | CR22: V1_42 | CS22: 4 | CT22: 2 | CU22: 0 | CV22: 0 | CW22: 0 | CX22: 0 | CY22: 1 | CZ22: 0
B23: 4 | D23: V2_02 | E23: hCom2 | F23: Expanded | G23: SI & LI | H23: 16 | AK23: 0.014846177 | AL23: 0.014846177 | AM23: 0 | AN23: 0.011345393 | AO23: 0.014846177 | AP23: 0.016358024 | AQ23: 0.016358024 | AR23: 0.023996528 | AS23: 0.014846177 | AT23: 0.018400851 | AU23: 0.013900186 | AV23: 0.0068447276 | AW23: 0.016944992 | AX23: 0.014846177 | AY23: 0.018400851 | AZ23: 0.011345393 | BA23: 0.0068447276 | BB23: 0 | BC23: 0.0099397324 | BD23: 0.29659652 | BE23: 0.86601657 | BF23: 0.013974679 | BG23: 0.032948606 | BH23: 0.012548987 | BI23: 0.02400045 | BJ23: 0.014846177 | BK23: 0.0068737409 | BL23: 0.013043378 | BM23: 0.0023730755 | BN23: 0.012548987 | BO23: 0.010421398 | BP23: 0.0023730755 | BQ23: 0.011345393 | BR23: 0.016669197 | BS23: 0.0068447276 | BT23: 0.01489305 | BU23: 0.019912698 | BV23: 0.0068737409 | BW23: 0.016944992 | BX23: 0.01285724 | BY23: 0 | BZ23: 0.0039926463 | CA23: 0.0063657219 | CB23: 0.0068447276 | CC23: 0.02400045 | CD23: 0.0049239478 | CE23: 0.0045006654 | CF23: 0.013651016 | CG23: 0 | CH23: 0.0094246132 | CI23: 0.01297227 | CJ23: 0.014440398 | CK23: 0.015024212 | CL23: 0.0094246132 | CM23: 0.014440398 | CN23: 0.0049239478 | CR23: V2_02 | CS23: 6 | CT23: 10 | CU23: 0 | CV23: 0 | CW23: 0 | CX23: 0 | CY23: 0 | CZ23: 0
B24: 5 | D24: V2_41 | E24: hCom2 | F24: Single | G24: SI | H24: 1 | AK24: 0.0055400012 | AL24: 0.0055400012 | AM24: 0.0041801356 | AN24: 0.0073495554 | AO24: 0.0041801356 | AP24: 0.018576873 | AQ24: 0.0088378995 | AR24: 0.0084112705 | AS24: 0.0084112705 | AT24: 0.0055400012 | AU24: 0.0055400012 | AV24: 0.0097711361 | AW24: 0.008411115 | AX24: 0.0041801356 | AY24: 0.005981446 | AZ24: 0.0092908212 | BA24: 0.0041801356 | BB24: 0.0058352354 | BC24: 0.0041801356 | BD24: 1.1029439 | BE24: 0.36316751 | BF24: 0.0041801356 | BG24: 0.0093902401 | BH24: 0.015500131 | BI24: 0.010750106 | BJ24: 0.0084112705 | BK24: 0.0050021414 | BL24: 0.01165817 | BM24: 0.0050021414 | BN24: 0.019413265 | BO24: 0.0093902401 | BP24: 0.0041801356 | BQ24: 0.0041801356 | BR24: 0.017333482 | BS24: 0.0041801356 | BT24: 0.0093902401 | BU24: 0.010750106 | BV24: 0.0008220058 | BW24: 0.0062847956 | BX24: 0.0055831388 | BY24: 0.0050021414 | BZ24: 0.011375429 | CA24: 0.012208523 | CB24: 0.0013598656 | CC24: 0.011319996 | CD24: 0.0046215804 | CE24: 0.0092908212 | CF24: 0.0084112705 | CG24: 0.0046215804 | CH24: 0.0046215804 | CI24: 0.008411115 | CJ24: 0.0046215804 | CK24: 0.008411115 | CL24: 0.0046215804 | CM24: 0.0084112705 | CN24: 0.0094573256 | CR24: V2_41 | CS24: 1 | CT24: 0 | CU24: 0 | CV24: 0 | CW24: 0 | CX24: 0 | CY24: 0 | CZ24: 0
B25: 6 | D25: V1_60 | E25: hCom1 | F25: Single | G25: LI | H25: 1 | AK25: 0.56811847 | AL25: 1.2589271 | AM25: 0.85902435 | AN25: 0.75189774 | AO25: 0.59381923 | AP25: 2.9298596 | AQ25: 2.4782306 | AR25: 1.8459009 | AS25: 0.084155702 | AT25: 1.4351403 | AU25: 0.054115654 | AV25: 1.4243383 | AW25: 0.51970806 | AX25: 1.0171955 | AY25: 1.0994162 | AZ25: 0.12332175 | BA25: 0.12148472 | BB25: 0.0096366464 | BC25: 0.53993059 | BD25: 0.0018944094 | BE25: 0.00380297 | BF25: 0.0097593076 | BG25: 0.011273695 | BH25: 0.014466598 | BI25: 0.0094121148 | BJ25: 0.0048514354 | BK25: 0.0096366464 | BL25: 0.01937447 | BM25: 0.0072245109 | BN25: 0.012514619 | BO25: 0.0085881811 | BP25: 0.0072245109 | BQ25: 0.0048514354 | BR25: 0.014466598 | BS25: 0.0048514354 | BT25: 0.0076631838 | BU25: 0.0076631838 | BV25: 0.0072245109 | BW25: 0.0076631838 | BX25: 0.005725841 | BY25: 0.0048514354 | BZ25: 0.0076631838 | CA25: 0.0061760456 | CB25: 0.0048514354 | CC25: 0.013301436 | CD25: 0.0094777454 | CE25: 0.0048514354 | CF25: 0.014150134 | CG25: 0.0094777454 | CH25: 0.0048514354 | CI25: 0.0096151626 | CJ25: 0.0048514354 | CK25: 0.005725841 | CL25: 0.0097593076 | CM25: 0.0048514354 | CN25: 0.0048514354 | CR25: V1_60 | CS25: 0 | CT25: 0 | CU25: 0 | CV25: 0 | CW25: 1 | CX25: 0 | CY25: 0 | CZ25: 0
B26: 7 | D26: V2_28 | E26: hCom2 | F26: Multiple | G26: LI | H26: 2 | AK26: 1.4340228 | AL26: 1.6959395 | AM26: 1.3083384 | AN26: 1.3326753 | AO26: 0.71032356 | AP26: 2.8743068 | AQ26: 2.2352111 | AR26: 1.7640777 | AS26: 0.46859955 | AT26: 2.3701583 | AU26: 0.15368651 | AV26: 1.7261639 | AW26: 0.813757 | AX26: 1.0002468 | AY26: 2.1446357 | AZ26: 0.17791441 | BA26: 0.073660407 | BB26: 0.0018253759 | BC26: 2.4565517 | BD26: 0.010720527 | BE26: 0.018288711 | BF26: 0.0097051078 | BG26: 0.01675528 | BH26: 0.012269329 | BI26: 0.029675306 | BJ26: 0.012096615 | BK26: 0.0038053317 | BL26: 0.012269329 | BM26: 0.0038053317 | BN26: 0.015008702 | BO26: 0.021729578 | BP26: 0.0038053317 | BQ26: 0.012096615 | BR26: 0.012924189 | BS26: 0.01634816 | BT26: 0.016918836 | BU26: 0.014737352 | BV26: 0 | BW26: 0.01703512 | BX26: 0.014737352 | BY26: 0 | BZ26: 0.012924189 | CA26: 0.010720527 | CB26: 0.0079162632 | CC26: 0.036275603 | CD26: 0.011915135 | CE26: 0.018049506 | CF26: 0.015720467 | CG26: 0.0058997761 | CH26: 0.011915135 | CI26: 0.024839323 | CJ26: 0.011915135 | CK26: 0.024839323 | CL26: 0.01773561 | CM26: 0.0097051078 | CN26: 0.0058997761 | CR26: V2_28 | CS26: 1 | CT26: 0 | CU26: 0 | CV26: 0 | CW26: 1 | CX26: 0 | CY26: 0 | CZ26: 0
B27: 8 | D27: V2_17 | E27: hCom2 | F27: Expanded | G27: LI | H27: 3 | AK27: 1.309968 | AL27: 3.2082776 | AM27: 2.3074777 | AN27: 1.7682951 | AO27: 2.5779179 | AP27: 3.4515312 | AQ27: 2.9047767 | AR27: 2.8364873 | AS27: 0.9897716 | AT27: 2.912207 | AU27: 0.52580739 | AV27: 2.7940268 | AW27: 1.1052982 | AX27: 0.16499471 | AY27: 1.2330458 | AZ27: 1.5659619 | BA27: 1.3846467 | BB27: 0.012010993 | BC27: 3.4638435 | BD27: 0.005687185 | BE27: 0.0037803858 | BF27: 0.01255758 | BG27: 0.0072933214 | BH27: 0.013477442 | BI27: 0.012473008 | BJ27: 0.015333012 | BK27: 0.0083284281 | BL27: 0.015980062 | BM27: 0.0083284281 | BN27: 0.015214289 | BO27: 0.008711237 | BP27: 0.0083284281 | BQ27: 0.01110386 | BR27: 0.011586285 | BS27: 0.01110386 | BT27: 0.028851146 | BU27: 0.011408548 | BV27: 0.0039810996 | BW27: 0.011475185 | BX27: 0.0079244461 | BY27: 0.0041427908 | BZ27: 0.0076051851 | CA27: 0.0094305611 | CB27: 0.01110386 | CC27: 0.0061979145 | CD27: 0.0039810996 | CE27: 0.0039810996 | CF27: 0.0083284281 | CG27: 0.0039810996 | CH27: 0.0080104995 | CI27: 0.005687185 | CJ27: 0.0039810996 | CK27: 0.0037803858 | CL27: 0.0080104995 | CM27: 0.0041427908 | CN27: 0.010820049 | CR27: V2_17 | CS27: 2 | CT27: 0 | CU27: 0 | CV27: 0 | CW27: 0 | CX27: 0 | CY27: 0 | CZ27: 1
B28: 9 | D28: V2_10 | E28: hCom2 | F28: Expanded | G28: SI & LI | H28: 6 | AK28: 0.82707359 | AL28: 1.5736891 | AM28: 2.1939968 | AN28: 1.2574876 | AO28: 1.2209417 | AP28: 3.0936739 | AQ28: 2.4178523 | AR28: 1.9803501 | AS28: 0.921346 | AT28: 1.7804742 | AU28: 0.19791998 | AV28: 1.8122792 | AW28: 0.68981691 | AX28: 0.066613553 | AY28: 1.0959932 | AZ28: 0.74485929 | BA28: 0.64406323 | BB28: 0.0066020123 | BC28: 2.5554715 | BD28: 0.0022855291 | BE28: 0.0022855291 | BF28: 0 | BG28: 0.0078023247 | BH28: 0.008817307 | BI28: 0.01481671 | BJ28: 0.0084978663 | BK28: 0.004785211 | BL28: 0.015406587 | BM28: 0.0066020123 | BN28: 0.015831692 | BO28: 0.006908721 | BP28: 0.0066020123 | BQ28: 0 | BR28: 0.0092467816 | BS28: 0.0042289367 | BT28: 0.01481671 | BU28: 0.0078023247 | BV28: 0.0023730755 | BW28: 0.0092467816 | BX28: 0.0045883703 | BY28: 0 | BZ28: 0.0092817965 | CA28: 0.0046586047 | CB28: 0.0042289367 | CC28: 0.010122675 | CD28: 0.0042289367 | CE28: 0 | CF28: 0.0042289367 | CG28: 0.0042289367 | CH28: 0.012025835 | CI28: 0.0045883703 | CJ28: 0 | CK28: 0.006908721 | CL28: 0.0042289367 | CM28: 0.0039457118 | CN28: 0.0042289367 | CR28: V2_10 | CS28: 1 | CT28: 0 | CU28: 0 | CV28: 0 | CW28: 5 | CX28: 0 | CY28: 0 | CZ28: 0
B29: 10 | D29: V2_16 | E29: hCom2 | F29: Expanded | G29: LI | H29: 3 | AK29: 0.33773839 | AL29: 2.1637362 | AM29: 1.2640353 | AN29: 0.86652534 | AO29: 1.3763398 | AP29: 2.5924451 | AQ29: 1.8512089 | AR29: 2.087932 | AS29: 0.48905747 | AT29: 1.7716854 | AU29: 0.21623907 | AV29: 2.0900454 | AW29: 0.33099713 | AX29: 0.012069883 | AY29: 0.77229334 | AZ29: 0.85381409 | BA29: 0.67736359 | BB29: 0.011314318 | BC29: 1.5405569 | BD29: 0.0023478368 | BE29: 0.0023478368 | BF29: 0.014302346 | BG29: 0.0072946234 | BH29: 0.016586687 | BI29: 0.0070977451 | BJ29: 0.004721714 | BK29: 0.011314318 | BL29: 0.021400091 | BM29: 0.004721714 | BN29: 0.0094353966 | BO29: 0.0065390585 | BP29: 0.004721714 | BQ29: 0.012069883 | BR29: 0.014785002 | BS29: 0.0094889421 | BT29: 0.01450231 | BU29: 0.0070977451 | BV29: 0.0056473375 | BW29: 0.0095002358 | BX29: 0.0070977451 | BY29: 0.0065470899 | BZ29: 0.0047136825 | CA29: 0.0065390585 | CB29: 0.004721714 | CC29: 0.0047136825 | CD29: 0.01108288 | CE29: 0.014152951 | CF29: 0.024633335 | CG29: 0.014152951 | CH29: 0.014526206 | CI29: 0.008109306 | CJ29: 0.01108288 | CK29: 0.008109306 | CL29: 0.011596627 | CM29: 0.0094889421 | CN29: 0.0038219615 | CR29: V2_16 | CS29: 1 | CT29: 0 | CU29: 0 | CV29: 0 | CW29: 2 | CX29: 0 | CY29: 0 | CZ29: 0
B30: 11 | D30: V1_28 | E30: hCom1 | F30: Expanded | G30: SI & LI | H30: 9 | AK30: 0.46201496 | AL30: 1.4124267 | AM30: 1.242588 | AN30: 1.0432481 | AO30: 1.0708675 | AP30: 2.3926365 | AQ30: 1.7955453 | AR30: 1.9750225 | AS30: 0.41136722 | AT30: 1.8773739 | AU30: 0.12988611 | AV30: 1.6771277 | AW30: 0.73171651 | AX30: 0.63597563 | AY30: 1.5033517 | AZ30: 0.4101721 | BA30: 0.29133038 | BB30: 0.01116753 | BC30: 1.684635 | BD30: 0.004787304 | BE30: 0.012136232 | BF30: 0.015915165 | BG30: 0.016381418 | BH30: 0.01267874 | BI30: 0.012446004 | BJ30: 0.0092610835 | BK30: 0.0082938829 | BL30: 0.015124987 | BM30: 0 | BN30: 0.012126325 | BO30: 0.012126325 | BP30: 0.0057010831 | BQ30: 0.013125147 | BR30: 0.010253751 | BS30: 0.011594114 | BT30: 0.018806407 | BU30: 0.013453176 | BV30: 0.01116753 | BW30: 0.01100693 | BX30: 0.0085819405 | BY30: 0.0054664469 | BZ30: 0.0023832967 | CA30: 0.010039729 | CB30: 0.017060561 | CC30: 0.018806407 | CD30: 0.020521026 | CE30: 0.015407685 | CF30: 0.015407685 | CG30: 0.015407685 | CH30: 0.010390386 | CI30: 0.024713118 | CJ30: 0.015407685 | CK30: 0.014728542 | CL30: 0.0099412383 | CM30: 0.015407685 | CN30: 0.0099412383 | CR30: V1_28 | CS30: 3 | CT30: 0 | CU30: 0 | CV30: 0 | CW30: 5 | CX30: 1 | CY30: 0 | CZ30: 0
B31: 12 | D31: V1_32 | E31: hCom1 | F31: Expanded | G31: LI | H31: 3 | AK31: 1.0462252 | AL31: 2.1251264 | AM31: 1.4843366 | AN31: 1.2729966 | AO31: 1.0729896 | AP31: 3.1630715 | AQ31: 2.6301427 | AR31: 2.4140421 | AS31: 0.49255102 | AT31: 2.335393 | AU31: 0.15762352 | AV31: 2.1454796 | AW31: 0.64171487 | AX31: 0.62615971 | AY31: 1.7463406 | AZ31: 0.46485368 | BA31: 0.35417895 | BB31: 0.0083567322 | BC31: 1.6625576 | BD31: 0.003612887 | BE31: 0.0060087813 | BF31: 0.0076350493 | BG31: 0.016346135 | BH31: 0.012256976 | BI31: 0.026364216 | BJ31: 0.015549879 | BK31: 0.005239155 | BL31: 0.0079589697 | BM31: 0.0037313734 | BN31: 0.012256976 | BO31: 0.0063676888 | BP31: 0.0037313734 | BQ31: 0.011551905 | BR31: 0.010099062 | BS31: 0.0078205318 | BT31: 0.018522094 | BU31: 0.014188221 | BV31: 0.005239155 | BW31: 0.012048128 | BX31: 0.010249149 | BY31: 0.0015077816 | BZ31: 0.0021051054 | CA31: 0.0078754704 | CB31: 0.015876714 | CC31: 0.020344109 | CD31: 0.0039036759 | CE31: 0.011931576 | CF31: 0.0076350493 | CG31: 0.0078801822 | CH31: 0.019791367 | CI31: 0.010271365 | CJ31: 0.0076350493 | CK31: 0.010271365 | CL31: 0.0076350493 | CM31: 0.011611556 | CN31: 0.0076350493 | CR31: V1_32 | CS31: 2 | CT31: 0 | CU31: 0 | CV31: 0 | CW31: 1 | CX31: 0 | CY31: 0 | CZ31: 0
... B57: 36 | D57: V2_05 | E57: hCom2 | F57: Expanded | G57: SI & LI | H57: 8 | AK57: 0.004649419 | AL57: 0.0023125108 | AM57: 0.004649419 | AN57: 0.0023125108 | AO57: 0.004649419 | AP57: 0.010346626 | AQ57: 0.0061488025 | AR57: 0.0023125108 | AS57: 0.0023125108 | AT57: 0.0023125108 | AU57: 0.0023125108 | AV57: 0.0023125108 | AW57: 0.0082376632 | AX57: 0.0023125108 | AY57: 0.0023125108 | AZ57: 0.0023125108 | BA57: 0.0023125108 | BB57: 0.0046855863 | BC57: 0.0079387147 | BD57: 0.0044033245 | BE57: 0.0082376632 | BF57: 0.0056018065 | BG57: 0.011600652 | BH57: 0.012659137 | BI57: 0.011600652 | BJ57: 0.004649419 | BK57: 0.0046855863 | BL57: 0.008729177 | BM57: 0.0070224945 | BN57: 0.012887082 | BO57: 0.014849058 | BP57: 0.0046855863 | BQ57: 0.0023125108 | BR57: 0.014788493 | BS57: 0.0023125108 | BT57: 0.0061488025 | BU57: 0.0082376632 | BV57: 0.0023125108 | BW57: 0.010346626 | BX57: 0.010346626 | BY57: 0.0046855863 | BZ57: 0.002030249 | CA57: 0.0082376632 | CB57: 0.004649419 | CC57: 0.017989019 | CD57: 0.0056018065 | CE57: 0.0056018065 | CF57: 0.0056018065 | CG57: 0.0079387147 | CH57: 0.0089469305 | CI57: 0.0061488025 | CJ57: 0.0089469305 | CK57: 0.0082376632 | CL57: 0.0023125108 | CM57: 0.0032892958 | CN57: 0.078302115 | CR57: V2_05 | CS57: 0 | CT57: 0 | CU57: 2 | CV57: 3 | CW57: 0 | CX57: 0 | CY57: 2 | CZ57: 1

Sheet Sheet1
B1: Coprococcus eutactus ATCC 27759 | C1: Eubacterium rectale ATCC 33656 | D1: Tyzzerella nexilis DSM 1787 | E1: Clostridium sp. L2-50 | F1: Clostridium sp. M62/1 | G1: Clostridium bolteae ATCC BAA-613 | H1: Clostridium hathewayi DSM 13479 | I1: Dorea formicigenerans ATCC 27755 | J1: Dorea longicatena DSM 13814 | K1: Blautia hansenii DSM 20583 | L1: Marvinbryantia formatexigens DSM 14469 (Bryantella formatexigens) | M1: Ruminococcus torques ATCC 27756 | N1: Subdoligranulum variabile DSM 15176 | O1: Eubacterium ventriosum ATCC 27560 DSM 3988 | P1: Anaerobutyricum hallii DSM 3353 (Eubacterium hallii) | Q1: Ruminococcus lactaris ATCC 29176 | R1: Holdemanella biformis DSM 3989 | S1: Collinsella stercoris DSM 13279 | T1: Solobacterium moorei DSM 22971 | U1: Chaw | V1: GF pellet | W1: Bacteroides coprophilus DSM 18228 | X1: Bacteroides dorei 5_1_36/D4 (HM 29) | Y1: Bacteroides eggerthii DSM 20697 | Z1: Bacteroides sp. 3_1_19 | AA1: Bacteroides plebeius DSM 17135 | AB1: Bacteroides coprocola DSM 17136 | AC1: Bacteroides stercoris ATCC 43183 DSMZ 19555 | AD1: Ruminococcus gnavus ATCC 29149 | AE1: Clostridium scindens ATCC 35704 | AF1: Clostridium asparagiforme DSM 15981 | AG1: Clostridium leptum DSM 753 | AH1: Coprococcus comes ATCC 27758 | AI1: Butyrivibrio crossotus DSM 2876 | AJ1: Parabacteroides merdae DSMZ 19495 (also ATCC 43184) | AK1: Parabacteroides johnsonii DSM 18315 | AL1: Parabacteroides sp. D13 | AM1: Eubacterium siraeum DSM 15702 | AN1: Anaerostipes caccae DSM 14662 | AO1: Bacteroides cellulosilyticus DSM 14838 | AP1: Acidaminococcus fermentans DSM 20731 | AQ1: Ethanoligenens harbinense YUAN-3 DSMZ 18485 | AR1: Veillonella dispar ATCC 17748 | AS1: Veillonella sp. 6_1_27 HM 49 | AT1: Clostridium sporogenes ATCC 15579 | AU1: Ruminococcus albus strain 8 | AV1: Ruminococcus bromii ATCC | AW1: Veillonella sp. 3_1_44 HM 64 | AX1: Megasphaera DSMZ 102144 | AY1: Blautia sp. KLE 1732 (HM 1032) | AZ1: Bilophila wadsworthia ATCC 49260 | BA1: Subdoligranulum sp. 4_3_54A2FAA | BB1: Alistipes senegalensis JC50/DSM 25460 | BC1: Blautia wexlerae DSM 19850 | BD1: Intestinimonas butyriciproducens DSM 26588 | BE1: Burkholderiales bacterium 1_1_47
A2: GF_6 | B2: 0.004721714 | C2: 0.004721714 | D2: 0.0094889421 | E2: 0.0094889421 | F2: 0.0094889421 | G2: 0.0086331162 | H2: 0.018986869 | I2: 0.037853909 | J2: 0.004721714 | K2: 0.010676679 | L2: 0.004721714 | M2: 0.004721714 | N2: 0.0081031727 | O2: 0.0094889421 | P2: 0.0076758727 | Q2: 0.004721714 | R2: 0.004721714 | S2: 0.00754915 | T2: 0.017672106 | U2: 0.0017061746 | V2: 0.0025087334 | W2: 0.011997676 | X2: 0.005149014 | Y2: 0.016374803 | Z2: 0.011587275 | AA2: 0.0094889421 | AB2: 0.012316378 | AC2: 0.014637956 | AD2: 0.00754915 | AE2: 0.0081441964 | AF2: 0.0062499184 | AG2: 0.00754915 | AH2: 0.0094889421 | AI2: 0.018122058 | AJ2: 0.004721714 | AK2: 0.012159227 | AL2: 0.0086331162 | AM2: 0.00754915 | AN2: 0.0086331162 | AO2: 0.005149014 | AP2: 0.00754915 | AQ2: 0.0086331162 | AR2: 0.009713297 | AS2: 0.0094889421 | AT2: 0.009377447 | AU2: 0.012367985 | AV2: 0.012367985 | AW2: 0.019765949 | AX2: 0.0097788878 | AY2: 0.0097788878 | AZ2: 0.0059312159 | BA2: 0.0072304474 | BB2: 0.0084796562 | BC2: 0.011997676 | BD2: 0.014546116 | BE2: 0.0072304474
A3: V1_33 | B3: 0.010956994 | C3: 0.010956994 | D3: 0.0077090076 | E3: 0.0073546658 | F3: 0.0073546658 | G3: 0.026620938 | H3: 0.014175755 | I3: 0.014798768 | J3: 0.0073546658 | K3: 0.010956994 | L3: 0.010808182 | M3: 0.0073546658 | N3: 0.014175755 | O3: 0.0073546658 | P3: 0.010956994 | Q3: 0.0073546658 | R3: 0.0035493341 | S3: 0 | T3: 0.0078801822 | U3: 1.0630623 | V3: 0.84921555 | W3: 0.0077090076 | X3: 0.01561566 | Y3: 0.014431752 | Z3: 0.023616086 | AA3: 0.014798768 | AB3: 0 | AC3: 0.010125717 | AD3: 0.0038053317 | AE3: 0.016111102 | AF3: 0.0063203857 | AG3: 0.0038053317 | AH3: 0.0073546658 | AI3: 0.014431752 | AJ3: 0.0035493341 | AK3: 0.0098697198 | AL3: 0.014175755 | AM3: 0.0015077816 | AN3: 0.017778083 | AO3: 0.01561566 | AP3: 0 | AQ3: 0.01062642 | AR3: 0.0063203857 | AS3: 0.0071516628 | AT3: 0.025816884 | AU3: 0.0039036759 | AV3: 0.0039036759 | AW3: 0.015736908 | AX3: 0.0039036759 | AY3: 0.011685514 | AZ3: 0.014530096 | BA3: 0.011685514 | BB3: 0.0080990177 | BC3: 0.0077090076 | BD3: 0.0077090076 | BE3: 0.0077090076
A4: V1_42 | B4: 0.011242123 | C4: 0.0055808118 | D4: 0 | E4: 0.0055808118 | F4: 0 | G4: 0.011623692 | H4: 0.0092584812 | I4: 0.0055808118 | J4: 0 | K4: 0 | L4: 0 | M4: 0 | N4: 0.0069137695 | O4: 0 | P4: 0.0055808118 | Q4: 0 | R4: 0 | S4: 0.0070885934 | T4: 0 | U4: 0.24937731 | V4: 0.092759105 | W4: 0.0055808118 | X4: 0.0045892918 | Y4: 0.012494581 | Z4: 0.0069137695 | AA4: 0.011242123 | AB4: 0.0070885934 | AC4: 0.012494581 | AD4: 0.0086300005 | AE4: 0.014839293 | AF4: 0.013131474 | AG4: 0.0070885934 | AH4: 0.0055808118 | AI4: 0.014839293 | AJ4: 0 | AK4: 0.0092584812 | AL4: 0.0092584812 | AM4: 0.0015077816 | AN4: 0.011623692 | AO4: 0.0069137695 | AP4: 0 | AQ4: 0.011623692 | AR4: 0.01230767 | AS4: 0 | AT4: 0.0092584812 | AU4: 0.0039565864 | AV4: 0.0095373982 | AW4: 0.0095373982 | AX4: 0.0039565864 | AY4: 0.0039565864 | AZ4: 0.0045892918 | BA4: 0.0055808118 | BB4: 0.0045892918 | BC4: 0.0095373982 | BD4: 0 | BE4: 0
A5: V2_02 | B5: 0.014846177 | C5: 0.014846177 | D5: 0 | E5: 0.011345393 | F5: 0.014846177 | G5: 0.016358024 | H5: 0.016358024 | I5: 0.023996528 | J5: 0.014846177 | K5: 0.018400851 | L5: 0.013900186 | M5: 0.0068447276 | N5: 0.016944992 | O5: 0.014846177 | P5: 0.018400851 | Q5: 0.011345393 | R5: 0.0068447276 | S5: 0 | T5: 0.0099397324 | U5: 0.29659652 | V5: 0.86601657 | W5: 0.013974679 | X5: 0.032948606 | Y5: 0.012548987 | Z5: 0.02400045 | AA5: 0.014846177 | AB5: 0.0068737409 | AC5: 0.013043378 | AD5: 0.0023730755 | AE5: 0.012548987 | AF5: 0.010421398 | AG5: 0.0023730755 | AH5: 0.011345393 | AI5: 0.016669197 | AJ5: 0.0068447276 | AK5: 0.01489305 | AL5: 0.019912698 | AM5: 0.0068737409 | AN5: 0.016944992 | AO5: 0.01285724 | AP5: 0 | AQ5: 0.0039926463 | AR5: 0.0063657219 | AS5: 0.0068447276 | AT5: 0.02400045 | AU5: 0.0049239478 | AV5: 0.0045006654 | AW5: 0.013651016 | AX5: 0 | AY5: 0.0094246132 | AZ5: 0.01297227 | BA5: 0.014440398 | BB5: 0.015024212 | BC5: 0.0094246132 | BD5: 0.014440398 | BE5: 0.0049239478
A6: V2_41 | B6: 0.0055400012 | C6: 0.0055400012 | D6: 0.0041801356 | E6: 0.0073495554 | F6: 0.0041801356 | G6: 0.018576873 | H6: 0.0088378995 | I6: 0.0084112705 | J6: 0.0084112705 | K6: 0.0055400012 | L6: 0.0055400012 | M6: 0.0097711361 | N6: 0.008411115 | O6: 0.0041801356 | P6: 0.005981446 | Q6: 0.0092908212 | R6: 0.0041801356 | S6: 0.0058352354 | T6: 0.0041801356 | U6: 1.1029439 | V6: 0.36316751 | W6: 0.0041801356 | X6: 0.0093902401 | Y6: 0.015500131 | Z6: 0.010750106 | AA6: 0.0084112705 | AB6: 0.0050021414 | AC6: 0.01165817 | AD6: 0.0050021414 | AE6: 0.019413265 | AF6: 0.0093902401 | AG6: 0.0041801356 | AH6: 0.0041801356 | AI6: 0.017333482 | AJ6: 0.0041801356 | AK6: 0.0093902401 | AL6: 0.010750106 | AM6: 0.0008220058 | AN6: 0.0062847956 | AO6: 0.0055831388 | AP6: 0.0050021414 | AQ6: 0.011375429 | AR6: 0.012208523 | AS6: 0.0013598656 | AT6: 0.011319996 | AU6: 0.0046215804 | AV6: 0.0092908212 | AW6: 0.0084112705 | AX6: 0.0046215804 | AY6: 0.0046215804 | AZ6: 0.008411115 | BA6: 0.0046215804 | BB6: 0.008411115 | BC6: 0.0046215804 | BD6: 0.0084112705 | BE6: 0.0094573256
A7: V1_60 | B7: 0.56811847 | C7: 1.2589271 | D7: 0.85902435 | E7: 0.75189774 | F7: 0.59381923 | G7: 2.9298596 | H7: 2.4782306 | I7: 1.8459009 | J7: 0.084155702 | K7: 1.4351403 | L7: 0.054115654 | M7: 1.4243383 | N7: 0.51970806 | O7: 1.0171955 | P7: 1.0994162 | Q7: 0.12332175 | R7: 0.12148472 | S7: 0.0096366464 | T7: 0.53993059 | U7: 0.0018944094 | V7: 0.00380297 | W7: 0.0097593076 | X7: 0.011273695 | Y7: 0.014466598 | Z7: 0.0094121148 | AA7: 0.0048514354 | AB7: 0.0096366464 | AC7: 0.01937447 | AD7: 0.0072245109 | AE7: 0.012514619 | AF7: 0.0085881811 | AG7: 0.0072245109 | AH7: 0.0048514354 | AI7: 0.014466598 | AJ7: 0.0048514354 | AK7: 0.0076631838 | AL7: 0.0076631838 | AM7: 0.0072245109 | AN7: 0.0076631838 | AO7: 0.005725841 | AP7: 0.0048514354 | AQ7: 0.0076631838 | AR7: 0.0061760456 | AS7: 0.0048514354 | AT7: 0.013301436 | AU7: 0.0094777454 | AV7: 0.0048514354 | AW7: 0.014150134 | AX7: 0.0094777454 | AY7: 0.0048514354 | AZ7: 0.0096151626 | BA7: 0.0048514354 | BB7: 0.005725841 | BC7: 0.0097593076 | BD7: 0.0048514354 | BE7: 0.0048514354
A8: V2_28 | B8: 1.4340228 | C8: 1.6959395 | D8: 1.3083384 | E8: 1.3326753 | F8: 0.71032356 | G8: 2.8743068 | H8: 2.2352111 | I8: 1.7640777 | J8: 0.46859955 | K8: 2.3701583 | L8: 0.15368651 | M8: 1.7261639 | N8: 0.813757 | O8: 1.0002468 | P8: 2.1446357 | Q8: 0.17791441 | R8: 0.073660407 | S8: 0.0018253759 | T8: 2.4565517 | U8: 0.010720527 | V8: 0.018288711 | W8: 0.0097051078 | X8: 0.01675528 | Y8: 0.012269329 | Z8: 0.029675306 | AA8: 0.012096615 | AB8: 0.0038053317 | AC8: 0.012269329 | AD8: 0.0038053317 | AE8: 0.015008702 | AF8: 0.021729578 | AG8: 0.0038053317 | AH8: 0.012096615 | AI8: 0.012924189 | AJ8: 0.01634816 | AK8: 0.016918836 | AL8: 0.014737352 | AM8: 0 | AN8: 0.01703512 | AO8: 0.014737352 | AP8: 0 | AQ8: 0.012924189 | AR8: 0.010720527 | AS8: 0.0079162632 | AT8: 0.036275603 | AU8: 0.011915135 | AV8: 0.018049506 | AW8: 0.015720467 | AX8: 0.0058997761 | AY8: 0.011915135 | AZ8: 0.024839323 | BA8: 0.011915135 | BB8: 0.024839323 | BC8: 0.01773561 | BD8: 0.0097051078 | BE8: 0.0058997761
A9: V2_17 | B9: 1.309968 | C9: 3.2082776 | D9: 2.3074777 | E9: 1.7682951 | F9: 2.5779179 | G9: 3.4515312 | H9: 2.9047767 | I9: 2.8364873 | J9: 0.9897716 | K9: 2.912207 | L9: 0.52580739 | M9: 2.7940268 | N9: 1.1052982 | O9: 0.16499471 | P9: 1.2330458 | Q9: 1.5659619 | R9: 1.3846467 | S9: 0.012010993 | T9: 3.4638435 | U9: 0.005687185 | V9: 0.0037803858 | W9: 0.01255758 | X9: 0.0072933214 | Y9: 0.013477442 | Z9: 0.012473008 | AA9: 0.015333012 | AB9: 0.0083284281 | AC9: 0.015980062 | AD9: 0.0083284281 | AE9: 0.015214289 | AF9: 0.008711237 | AG9: 0.0083284281 | AH9: 0.01110386 | AI9: 0.011586285 | AJ9: 0.01110386 | AK9: 0.028851146 | AL9: 0.011408548 | AM9: 0.0039810996 | AN9: 0.011475185 | AO9: 0.0079244461 | AP9: 0.0041427908 | AQ9: 0.0076051851 | AR9: 0.0094305611 | AS9: 0.01110386 | AT9: 0.0061979145 | AU9: 0.0039810996 | AV9: 0.0039810996 | AW9: 0.0083284281 | AX9: 0.0039810996 | AY9: 0.0080104995 | AZ9: 0.005687185 | BA9: 0.0039810996 | BB9: 0.0037803858 | BC9: 0.0080104995 | BD9: 0.0041427908 | BE9: 0.010820049
A10: V2_10 | B10: 0.82707359 | C10: 1.5736891 | D10: 2.1939968 | E10: 1.2574876 | F10: 1.2209417 | G10: 3.0936739 | H10: 2.4178523 | I10: 1.9803501 | J10: 0.921346 | K10: 1.7804742 | L10: 0.19791998 | M10: 1.8122792 | N10: 0.68981691 | O10: 0.066613553 | P10: 1.0959932 | Q10: 0.74485929 | R10: 0.64406323 | S10: 0.0066020123 | T10: 2.5554715 | U10: 0.0022855291 | V10: 0.0022855291 | W10: 0 | X10: 0.0078023247 | Y10: 0.008817307 | Z10: 0.01481671 | AA10: 0.0084978663 | AB10: 0.004785211 | AC10: 0.015406587 | AD10: 0.0066020123 | AE10: 0.015831692 | AF10: 0.006908721 | AG10: 0.0066020123 | AH10: 0 | AI10: 0.0092467816 | AJ10: 0.0042289367 | AK10: 0.01481671 | AL10: 0.0078023247 | AM10: 0.0023730755 | AN10: 0.0092467816 | AO10: 0.0045883703 | AP10: 0 | AQ10: 0.0092817965 | AR10: 0.0046586047 | AS10: 0.0042289367 | AT10: 0.010122675 | AU10: 0.0042289367 | AV10: 0 | AW10: 0.0042289367 | AX10: 0.0042289367 | AY10: 0.012025835 | AZ10: 0.0045883703 | BA10: 0 | BB10: 0.006908721 | BC10: 0.0042289367 | BD10: 0.0039457118 | BE10: 0.0042289367
A11: V2_16 | B11: 0.33773839 | C11: 2.1637362 | D11: 1.2640353 | E11: 0.86652534 | F11: 1.3763398 | G11: 2.5924451 | H11: 1.8512089 | I11: 2.087932 | J11: 0.48905747 | K11: 1.7716854 | L11: 0.21623907 | M11: 2.0900454 | N11: 0.33099713 | O11: 0.012069883 | P11: 0.77229334 | Q11: 0.85381409 | R11: 0.67736359 | S11: 0.011314318 | T11: 1.5405569 | U11: 0.0023478368 | V11: 0.0023478368 | W11: 0.014302346 | X11: 0.0072946234 | Y11: 0.016586687 | Z11: 0.0070977451 | AA11: 0.004721714 | AB11: 0.011314318 | AC11: 0.021400091 | AD11: 0.004721714 | AE11: 0.0094353966 | AF11: 0.0065390585 | AG11: 0.004721714 | AH11: 0.012069883 | AI11: 0.014785002 | AJ11: 0.0094889421 | AK11: 0.01450231 | AL11: 0.0070977451 | AM11: 0.0056473375 | AN11: 0.0095002358 | AO11: 0.0070977451 | AP11: 0.0065470899 | AQ11: 0.0047136825 | AR11: 0.0065390585 | AS11: 0.004721714 | AT11: 0.0047136825 | AU11: 0.01108288 | AV11: 0.014152951 | AW11: 0.024633335 | AX11: 0.014152951 | AY11: 0.014526206 | AZ11: 0.008109306 | BA11: 0.01108288 | BB11: 0.008109306 | BC11: 0.011596627 | BD11: 0.0094889421 | BE11: 0.0038219615
A12: V1_28 | B12: 0.46201496 | C12: 1.4124267 | D12: 1.242588 | E12: 1.0432481 | F12: 1.0708675 | G12: 2.3926365 | H12: 1.7955453 | I12: 1.9750225 | J12: 0.41136722 | K12: 1.8773739 | L12: 0.12988611 | M12: 1.6771277 | N12: 0.73171651 | O12: 0.63597563 | P12: 1.5033517 | Q12: 0.4101721 | R12: 0.29133038 | S12: 0.01116753 | T12: 1.684635 | U12: 0.004787304 | V12: 0.012136232 | W12: 0.015915165 | X12: 0.016381418 | Y12: 0.01267874 | Z12: 0.012446004 | AA12: 0.0092610835 | AB12: 0.0082938829 | AC12: 0.015124987 | AD12: 0 | AE12: 0.012126325 | AF12: 0.012126325 | AG12: 0.0057010831 | AH12: 0.013125147 | AI12: 0.010253751 | AJ12: 0.011594114 | AK12: 0.018806407 | AL12: 0.013453176 | AM12: 0.01116753 | AN12: 0.01100693 | AO12: 0.0085819405 | AP12: 0.0054664469 | AQ12: 0.0023832967 | AR12: 0.010039729 | AS12: 0.017060561 | AT12: 0.018806407 | AU12: 0.020521026 | AV12: 0.015407685 | AW12: 0.015407685 | AX12: 0.015407685 | AY12: 0.010390386 | AZ12: 0.024713118 | BA12: 0.015407685 | BB12: 0.014728542 | BC12: 0.0099412383 | BD12: 0.015407685 | BE12: 0.0099412383
A13: V1_32 | B13: 1.0462252 | C13: 2.1251264 | D13: 1.4843366 | E13: 1.2729966 | F13: 1.0729896 | G13: 3.1630715 | H13: 2.6301427 | I13: 2.4140421 | J13: 0.49255102 | K13: 2.335393 | L13: 0.15762352 | M13: 2.1454796 | N13: 0.64171487 | O13: 0.62615971 | P13: 1.7463406 | Q13: 0.46485368 | R13: 0.35417895 | S13: 0.0083567322 | T13: 1.6625576 | U13: 0.003612887 | V13: 0.0060087813 | W13: 0.0076350493 | X13: 0.016346135 | Y13: 0.012256976 | Z13: 0.026364216 | AA13: 0.015549879 | AB13: 0.005239155 | AC13: 0.0079589697 | AD13: 0.0037313734 | AE13: 0.012256976 | AF13: 0.0063676888 | AG13: 0.0037313734 | AH13: 0.011551905 | AI13: 0.010099062 | AJ13: 0.0078205318 | AK13: 0.018522094 | AL13: 0.014188221 | AM13: 0.005239155 | AN13: 0.012048128 | AO13: 0.010249149 | AP13: 0.0015077816 | AQ13: 0.0021051054 | AR13: 0.0078754704 | AS13: 0.015876714 | AT13: 0.020344109 | AU13: 0.0039036759 | AV13: 0.011931576 | AW13: 0.0076350493 | AX13: 0.0078801822 | AY13: 0.019791367 | AZ13: 0.010271365 | BA13: 0.0076350493 | BB13: 0.010271365 | BC13: 0.0076350493 | BD13: 0.011611556 | BE13: 0.0076350493
... A37: V2_05 | B37: 0.004649419 | C37: 0.0023125108 | D37: 0.004649419 | E37: 0.0023125108 | F37: 0.004649419 | G37: 0.010346626 | H37: 0.0061488025 | I37: 0.0023125108 | J37: 0.0023125108 | K37: 0.0023125108 | L37: 0.0023125108 | M37: 0.0023125108 | N37: 0.0082376632 | O37: 0.0023125108 | P37: 0.0023125108 | Q37: 0.0023125108 | R37: 0.0023125108 | S37: 0.0046855863 | T37: 0.0079387147 | U37: 0.0044033245 | V37: 0.0082376632 | W37: 0.0056018065 | X37: 0.011600652 | Y37: 0.012659137 | Z37: 0.011600652 | AA37: 0.004649419 | AB37: 0.0046855863 | AC37: 0.008729177 | AD37: 0.0070224945 | AE37: 0.012887082 | AF37: 0.014849058 | AG37: 0.0046855863 | AH37: 0.0023125108 | AI37: 0.014788493 | AJ37: 0.0023125108 | AK37: 0.0061488025 | AL37: 0.0082376632 | AM37: 0.0023125108 | AN37: 0.010346626 | AO37: 0.010346626 | AP37: 0.0046855863 | AQ37: 0.002030249 | AR37: 0.0082376632 | AS37: 0.004649419 | AT37: 0.017989019 | AU37: 0.0056018065 | AV37: 0.0056018065 | AW37: 0.0056018065 | AX37: 0.0079387147 | AY37: 0.0089469305 | AZ37: 0.0061488025 | BA37: 0.0089469305 | BB37: 0.0082376632 | BC37: 0.0023125108 | BD37: 0.0032892958 | BE37: 0.078302115

Sheet Raw value
B2: hCom# | F2: SUM | I2: Th subset | R2: 24 | S2: 27 | T2: 29 | U2: 31 | V2: 32 | W2: 34 | X2: 35 | Y2: 37 | Z2: 38 | AA2: 40 | AB2: 41 | AC2: 43 | AD2: 45 | AE2: 50 | AF2: 53 | AG2: 56 | AH2: 62 | AI2: 78 | AJ2: 94 | AK2: -1 | AL2: 0 | AM2: 4 | AN2: 5 | AO2: 6 | AP2: 12 | AQ2: 20 | AR2: 22 | AS2: 23 | AT2: 26 | AU2: 30 | AV2: 33 | AW2: 36 | AX2: 39 | AY2: 42 | AZ2: 44 | BA2: 46 | BB2: 52 | BC2: 66 | BD2: 68 | BE2: 69 | BF2: 74 | BG2: 76 | BH2: 77 | BI2: 86 | BJ2: 100 | BK2: 104 | BL2: 106 | BM2: 107 | BN2: 109 | BO2: 114 | BP2: 121 | BQ2: 123 | BR2: 124 | BS2: 125 | BT2: 127 | BU2: 131
B3: Strain | C3: Hyridoma | D3: Community | E3: Type | F3: Total | G3: Small intestine | H3: Large intestine | I3: Naïve | J3: Memory | K3: pTreg | L3: tTreg | M3: Th1 | N3: Th2 | O3: Th17 | P3: Fr4 Th | Q3: Other Effector Th | R3: Coprococcus eutactus ATCC 27759 | S3: Eubacterium rectale ATCC 33656 | T3: Tyzzerella nexilis DSM 1787 | U3: Clostridium sp. L2-50 | V3: Clostridium sp. M62/1 | W3: Clostridium bolteae ATCC BAA-613 | X3: Clostridium hathewayi DSM 13479 | Y3: Dorea formicigenerans ATCC 27755 | Z3: Dorea longicatena DSM 13814 | AA3: Blautia hansenii DSM 20583 | AB3: Marvinbryantia formatexigens DSM 14469 (Bryantella formatexigens) | AC3: Ruminococcus torques ATCC 27756 | AD3: Subdoligranulum variabile DSM 15176 | AE3: Eubacterium ventriosum ATCC 27560 DSM 3988 | AF3: Anaerobutyricum hallii DSM 3353 (Eubacterium hallii) | AG3: Ruminococcus lactaris ATCC 29176 | AH3: Holdemanella biformis DSM 3989 | AI3: Collinsella stercoris DSM 13279 | AJ3: Solobacterium moorei DSM 22971 | AK3: Chaw | AL3: GF pellet | AM3: Bacteroides coprophilus DSM 18228 | AN3: Bacteroides dorei 5_1_36/D4 (HM 29) | AO3: Bacteroides eggerthii DSM 20697 | AP3: Bacteroides sp. 3_1_19 | AQ3: Bacteroides plebeius DSM 17135 | AR3: Bacteroides coprocola DSM 17136 | AS3: Bacteroides stercoris ATCC 43183 DSMZ 19555 | AT3: Ruminococcus gnavus ATCC 29149 | AU3: Clostridium scindens ATCC 35704 | AV3: Clostridium asparagiforme DSM 15981 | AW3: Clostridium leptum DSM 753 | AX3: Coprococcus comes ATCC 27758 | AY3: Butyrivibrio crossotus DSM 2876 | AZ3: Parabacteroides merdae DSMZ 19495 (also ATCC 43184) | BA3: Parabacteroides johnsonii DSM 18315 | BB3: Parabacteroides sp. D13 | BC3: Eubacterium siraeum DSM 15702 | BD3: Anaerostipes caccae DSM 14662 | BE3: Bacteroides cellulosilyticus DSM 14838 | BF3: Acidaminococcus fermentans DSM 20731 | BG3: Ethanoligenens harbinense YUAN-3 DSMZ 18485 | BH3: Veillonella dispar ATCC 17748 | BI3: Veillonella sp. 6_1_27 HM 49 | BJ3: Clostridium sporogenes ATCC 15579 | BK3: Ruminococcus albus strain 8 | BL3: Ruminococcus bromii ATCC | BM3: Veillonella sp. 3_1_44 HM 64 | BN3: Megasphaera DSMZ 102144 | BO3: Blautia sp. KLE 1732 (HM 1032) | BP3: Bilophila wadsworthia ATCC 49260 | BQ3: Subdoligranulum sp. 4_3_54A2FAA | BR3: Alistipes senegalensis JC50/DSM 25460 | BS3: Blautia wexlerae DSM 19850 | BT3: Intestinimonas butyriciproducens DSM 26588 | BU3: Burkholderiales bacterium 1_1_47
A4: 1 | B4: GF_6 | C4: GF | D4: GF | E4: Expanded | F4: 4 | G4: 0 | H4: 4 | I4: 0 | J4: 0 | K4: 3 | L4: 1 | M4: 0 | N4: 0 | O4: 0 | P4: 0 | Q4: 0 | R4: 0.004721714 | S4: 0.004721714 | T4: 0.0094889421 | U4: 0.0094889421 | V4: 0.0094889421 | W4: 0.0086331162 | X4: 0.018986869 | Y4: 0.037853909 | Z4: 0.004721714 | AA4: 0.010676679 | AB4: 0.004721714 | AC4: 0.004721714 | AD4: 0.0081031727 | AE4: 0.0094889421 | AF4: 0.0076758727 | AG4: 0.004721714 | AH4: 0.004721714 | AI4: 0.00754915 | AJ4: 0.017672106 | AK4: 0.0017061746 | AL4: 0.0025087334 | AM4: 0.011997676 | AN4: 0.005149014 | AO4: 0.016374803 | AP4: 0.011587275 | AQ4: 0.0094889421 | AR4: 0.012316378 | AS4: 0.014637956 | AT4: 0.00754915 | AU4: 0.0081441964 | AV4: 0.0062499184 | AW4: 0.00754915 | AX4: 0.0094889421 | AY4: 0.018122058 | AZ4: 0.004721714 | BA4: 0.012159227 | BB4: 0.0086331162 | BC4: 0.00754915 | BD4: 0.0086331162 | BE4: 0.005149014 | BF4: 0.00754915 | BG4: 0.0086331162 | BH4: 0.009713297 | BI4: 0.0094889421 | BJ4: 0.009377447 | BK4: 0.012367985 | BL4: 0.012367985 | BM4: 0.019765949 | BN4: 0.0097788878 | BO4: 0.0097788878 | BP4: 0.0059312159 | BQ4: 0.0072304474 | BR4: 0.0084796562 | BS4: 0.011997676 | BT4: 0.014546116 | BU4: 0.0072304474
A5: 2 | B5: V1_33 | C5: =VLOOKUP(B5,Name!$B$7:$C$98,2, FALSE) -> H1-33 | D5: HCOM1 | E5: Expanded | F5: 7 | G5: 4 | H5: 3 | I5: 0 | J5: 1 | K5: 5 | L5: 1 | M5: 0 | N5: 0 | O5: 0 | P5: 0 | Q5: 0 | R5: 0.010956994 | S5: 0.010956994 | T5: 0.0077090076 | U5: 0.0073546658 | V5: 0.0073546658 | W5: 0.026620938 | X5: 0.014175755 | Y5: 0.014798768 | Z5: 0.0073546658 | AA5: 0.010956994 | AB5: 0.010808182 | AC5: 0.0073546658 | AD5: 0.014175755 | AE5: 0.0073546658 | AF5: 0.010956994 | AG5: 0.0073546658 | AH5: 0.0035493341 | AI5: 0 | AJ5: 0.0078801822 | AK5: 1.0630623 | AL5: 0.84921555 | AM5: 0.0077090076 | AN5: 0.01561566 | AO5: 0.014431752 | AP5: 0.023616086 | AQ5: 0.014798768 | AR5: 0 | AS5: 0.010125717 | AT5: 0.0038053317 | AU5: 0.016111102 | AV5: 0.0063203857 | AW5: 0.0038053317 | AX5: 0.0073546658 | AY5: 0.014431752 | AZ5: 0.0035493341 | BA5: 0.0098697198 | BB5: 0.014175755 | BC5: 0.0015077816 | BD5: 0.017778083 | BE5: 0.01561566 | BF5: 0 | BG5: 0.01062642 | BH5: 0.0063203857 | BI5: 0.0071516628 | BJ5: 0.025816884 | BK5: 0.0039036759 | BL5: 0.0039036759 | BM5: 0.015736908 | BN5: 0.0039036759 | BO5: 0.011685514 | BP5: 0.014530096 | BQ5: 0.011685514 | BR5: 0.0080990177 | BS5: 0.0077090076 | BT5: 0.0077090076 | BU5: 0.0077090076
A6: 3 | B6: V1_42 | C6: =VLOOKUP(B6,Name!$B$7:$C$98,2, FALSE) -> H1-34 | D6: HCOM1 | E6: Expanded | F6: 7 | G6: 5 | H6: 2 | I6: 0 | J6: 0 | K6: 4 | L6: 2 | M6: 0 | N6: 0 | O6: 0 | P6: 0 | Q6: 1 | R6: 0.011242123 | S6: 0.0055808118 | T6: 0 | U6: 0.0055808118 | V6: 0 | W6: 0.011623692 | X6: 0.0092584812 | Y6: 0.0055808118 | Z6: 0 | AA6: 0 | AB6: 0 | AC6: 0 | AD6: 0.0069137695 | AE6: 0 | AF6: 0.0055808118 | AG6: 0 | AH6: 0 | AI6: 0.0070885934 | AJ6: 0 | AK6: 0.24937731 | AL6: 0.092759105 | AM6: 0.0055808118 | AN6: 0.0045892918 | AO6: 0.012494581 | AP6: 0.0069137695 | AQ6: 0.011242123 | AR6: 0.0070885934 | AS6: 0.012494581 | AT6: 0.0086300005 | AU6: 0.014839293 | AV6: 0.013131474 | AW6: 0.0070885934 | AX6: 0.0055808118 | AY6: 0.014839293 | AZ6: 0 | BA6: 0.0092584812 | BB6: 0.0092584812 | BC6: 0.0015077816 | BD6: 0.011623692 | BE6: 0.0069137695 | BF6: 0 | BG6: 0.011623692 | BH6: 0.01230767 | BI6: 0 | BJ6: 0.0092584812 | BK6: 0.0039565864 | BL6: 0.0095373982 | BM6: 0.0095373982 | BN6: 0.0039565864 | BO6: 0.0039565864 | BP6: 0.0045892918 | BQ6: 0.0055808118 | BR6: 0.0045892918 | BS6: 0.0095373982 | BT6: 0 | BU6: 0
A7: 4 | B7: V2_02 | C7: =VLOOKUP(B7,Name!$B$7:$C$98,2, FALSE) -> H2-39 | D7: HCOM2 | E7: Expanded | F7: 16 | G7: 4 | H7: 12 | I7: 0 | J7: 0 | K7: 6 | L7: 10 | M7: 0 | N7: 0 | O7: 0 | P7: 0 | Q7: 0 | R7: 0.014846177 | S7: 0.014846177 | T7: 0 | U7: 0.011345393 | V7: 0.014846177 | W7: 0.016358024 | X7: 0.016358024 | Y7: 0.023996528 | Z7: 0.014846177 | AA7: 0.018400851 | AB7: 0.013900186 | AC7: 0.0068447276 | AD7: 0.016944992 | AE7: 0.014846177 | AF7: 0.018400851 | AG7: 0.011345393 | AH7: 0.0068447276 | AI7: 0 | AJ7: 0.0099397324 | AK7: 0.29659652 | AL7: 0.86601657 | AM7: 0.013974679 | AN7: 0.032948606 | AO7: 0.012548987 | AP7: 0.02400045 | AQ7: 0.014846177 | AR7: 0.0068737409 | AS7: 0.013043378 | AT7: 0.0023730755 | AU7: 0.012548987 | AV7: 0.010421398 | AW7: 0.0023730755 | AX7: 0.011345393 | AY7: 0.016669197 | AZ7: 0.0068447276 | BA7: 0.01489305 | BB7: 0.019912698 | BC7: 0.0068737409 | BD7: 0.016944992 | BE7: 0.01285724 | BF7: 0 | BG7: 0.0039926463 | BH7: 0.0063657219 | BI7: 0.0068447276 | BJ7: 0.02400045 | BK7: 0.0049239478 | BL7: 0.0045006654 | BM7: 0.013651016 | BN7: 0 | BO7: 0.0094246132 | BP7: 0.01297227 | BQ7: 0.014440398 | BR7: 0.015024212 | BS7: 0.0094246132 | BT7: 0.014440398 | BU7: 0.0049239478
A8: 5 | B8: V2_41 | C8: =VLOOKUP(B8,Name!$B$7:$C$98,2, FALSE) -> H2-04 | D8: HCOM2 | E8: Single | F8: 1 | G8: 1 | H8: 0 | I8: 0 | J8: 0 | K8: 1 | L8: 0 | M8: 0 | N8: 0 | O8: 0 | P8: 0 | Q8: 0 | R8: 0.0055400012 | S8: 0.0055400012 | T8: 0.0041801356 | U8: 0.0073495554 | V8: 0.0041801356 | W8: 0.018576873 | X8: 0.0088378995 | Y8: 0.0084112705 | Z8: 0.0084112705 | AA8: 0.0055400012 | AB8: 0.0055400012 | AC8: 0.0097711361 | AD8: 0.008411115 | AE8: 0.0041801356 | AF8: 0.005981446 | AG8: 0.0092908212 | AH8: 0.0041801356 | AI8: 0.0058352354 | AJ8: 0.0041801356 | AK8: 1.1029439 | AL8: 0.36316751 | AM8: 0.0041801356 | AN8: 0.0093902401 | AO8: 0.015500131 | AP8: 0.010750106 | AQ8: 0.0084112705 | AR8: 0.0050021414 | AS8: 0.01165817 | AT8: 0.0050021414 | AU8: 0.019413265 | AV8: 0.0093902401 | AW8: 0.0041801356 | AX8: 0.0041801356 | AY8: 0.017333482 | AZ8: 0.0041801356 | BA8: 0.0093902401 | BB8: 0.010750106 | BC8: 0.0008220058 | BD8: 0.0062847956 | BE8: 0.0055831388 | BF8: 0.0050021414 | BG8: 0.011375429 | BH8: 0.012208523 | BI8: 0.0013598656 | BJ8: 0.011319996 | BK8: 0.0046215804 | BL8: 0.0092908212 | BM8: 0.0084112705 | BN8: 0.0046215804 | BO8: 0.0046215804 | BP8: 0.008411115 | BQ8: 0.0046215804 | BR8: 0.008411115 | BS8: 0.0046215804 | BT8: 0.0084112705 | BU8: 0.0094573256
A9: 6 | B9: V1_60 | C9: =VLOOKUP(B9,Name!$B$7:$C$98,2, FALSE) -> H1-19 | D9: HCOM1 | E9: Single | F9: 1 | G9: 0 | H9: 1 | I9: 0 | J9: 0 | K9: 0 | L9: 0 | M9: 0 | N9: 0 | O9: 1 | P9: 0 | Q9: 0 | R9: 0.56811847 | S9: 1.2589271 | T9: 0.85902435 | U9: 0.75189774 | V9: 0.59381923 | W9: 2.9298596 | X9: 2.4782306 | Y9: 1.8459009 | Z9: 0.084155702 | AA9: 1.4351403 | AB9: 0.054115654 | AC9: 1.4243383 | AD9: 0.51970806 | AE9: 1.0171955 | AF9: 1.0994162 | AG9: 0.12332175 | AH9: 0.12148472 | AI9: 0.0096366464 | AJ9: 0.53993059 | AK9: 0.0018944094 | AL9: 0.00380297 | AM9: 0.0097593076 | AN9: 0.011273695 | AO9: 0.014466598 | AP9: 0.0094121148 | AQ9: 0.0048514354 | AR9: 0.0096366464 | AS9: 0.01937447 | AT9: 0.0072245109 | AU9: 0.012514619 | AV9: 0.0085881811 | AW9: 0.0072245109 | AX9: 0.0048514354 | AY9: 0.014466598 | AZ9: 0.0048514354 | BA9: 0.0076631838 | BB9: 0.0076631838 | BC9: 0.0072245109 | BD9: 0.0076631838 | BE9: 0.005725841 | BF9: 0.0048514354 | BG9: 0.0076631838 | BH9: 0.0061760456 | BI9: 0.0048514354 | BJ9: 0.013301436 | BK9: 0.0094777454 | BL9: 0.0048514354 | BM9: 0.014150134 | BN9: 0.0094777454 | BO9: 0.0048514354 | BP9: 0.0096151626 | BQ9: 0.0048514354 | BR9: 0.005725841 | BS9: 0.0097593076 | BT9: 0.0048514354 | BU9: 0.0048514354
A10: 7 | B10: V2_28 | C10: =VLOOKUP(B10,Name!$B$7:$C$98,2, FALSE) -> H2-20 | D10: HCOM2 | E10: Multiple | F10: 2 | G10: 0 | H10: 2 | I10: 0 | J10: 0 | K10: 1 | L10: 0 | M10: 0 | N10: 0 | O10: 1 | P10: 0 | Q10: 0 | R10: 1.4340228 | S10: 1.6959395 | T10: 1.3083384 | U10: 1.3326753 | V10: 0.71032356 | W10: 2.8743068 | X10: 2.2352111 | Y10: 1.7640777 | Z10: 0.46859955 | AA10: 2.3701583 | AB10: 0.15368651 | AC10: 1.7261639 | AD10: 0.813757 | AE10: 1.0002468 | AF10: 2.1446357 | AG10: 0.17791441 | AH10: 0.073660407 | AI10: 0.0018253759 | AJ10: 2.4565517 | AK10: 0.010720527 | AL10: 0.018288711 | AM10: 0.0097051078 | AN10: 0.01675528 | AO10: 0.012269329 | AP10: 0.029675306 | AQ10: 0.012096615 | AR10: 0.0038053317 | AS10: 0.012269329 | AT10: 0.0038053317 | AU10: 0.015008702 | AV10: 0.021729578 | AW10: 0.0038053317 | AX10: 0.012096615 | AY10: 0.012924189 | AZ10: 0.01634816 | BA10: 0.016918836 | BB10: 0.014737352 | BC10: 0 | BD10: 0.01703512 | BE10: 0.014737352 | BF10: 0 | BG10: 0.012924189 | BH10: 0.010720527 | BI10: 0.0079162632 | BJ10: 0.036275603 | BK10: 0.011915135 | BL10: 0.018049506 | BM10: 0.015720467 | BN10: 0.0058997761 | BO10: 0.011915135 | BP10: 0.024839323 | BQ10: 0.011915135 | BR10: 0.024839323 | BS10: 0.01773561 | BT10: 0.0097051078 | BU10: 0.0058997761
A11: 8 | B11: V2_17 | C11: =VLOOKUP(B11,Name!$B$7:$C$98,2, FALSE) -> H2-22 | D11: HCOM2 | E11: Expanded | F11: 3 | G11: 0 | H11: 3 | I11: 0 | J11: 1 | K11: 2 | L11: 0 | M11: 0 | N11: 0 | O11: 0 | P11: 0 | Q11: 0 | R11: 1.309968 | S11: 3.2082776 | T11: 2.3074777 | U11: 1.7682951 | V11: 2.5779179 | W11: 3.4515312 | X11: 2.9047767 | Y11: 2.8364873 | Z11: 0.9897716 | AA11: 2.912207 | AB11: 0.52580739 | AC11: 2.7940268 | AD11: 1.1052982 | AE11: 0.16499471 | AF11: 1.2330458 | AG11: 1.5659619 | AH11: 1.3846467 | AI11: 0.012010993 | AJ11: 3.4638435 | AK11: 0.005687185 | AL11: 0.0037803858 | AM11: 0.01255758 | AN11: 0.0072933214 | AO11: 0.013477442 | AP11: 0.012473008 | AQ11: 0.015333012 | AR11: 0.0083284281 | AS11: 0.015980062 | AT11: 0.0083284281 | AU11: 0.015214289 | AV11: 0.008711237 | AW11: 0.0083284281 | AX11: 0.01110386 | AY11: 0.011586285 | AZ11: 0.01110386 | BA11: 0.028851146 | BB11: 0.011408548 | BC11: 0.0039810996 | BD11: 0.011475185 | BE11: 0.0079244461 | BF11: 0.0041427908 | BG11: 0.0076051851 | BH11: 0.0094305611 | BI11: 0.01110386 | BJ11: 0.0061979145 | BK11: 0.0039810996 | BL11: 0.0039810996 | BM11: 0.0083284281 | BN11: 0.0039810996 | BO11: 0.0080104995 | BP11: 0.005687185 | BQ11: 0.0039810996 | BR11: 0.0037803858 | BS11: 0.0080104995 | BT11: 0.0041427908 | BU11: 0.010820049
A12: 9 | B12: V2_10 | C12: =VLOOKUP(B12,Name!$B$7:$C$98,2, FALSE) -> H2-29 | D12: HCOM2 | E12: Expanded | F12: 6 | G12: 1 | H12: 5 | I12: 0 | J12: 0 | K12: 1 | L12: 0 | M12: 0 | N12: 0 | O12: 5 | P12: 0 | Q12: 0 | R12: 0.82707359 | S12: 1.5736891 | T12: 2.1939968 | U12: 1.2574876 | V12: 1.2209417 | W12: 3.0936739 | X12: 2.4178523 | Y12: 1.9803501 | Z12: 0.921346 | AA12: 1.7804742 | AB12: 0.19791998 | AC12: 1.8122792 | AD12: 0.68981691 | AE12: 0.066613553 | AF12: 1.0959932 | AG12: 0.74485929 | AH12: 0.64406323 | AI12: 0.0066020123 | AJ12: 2.5554715 | AK12: 0.0022855291 | AL12: 0.0022855291 | AM12: 0 | AN12: 0.0078023247 | AO12: 0.008817307 | AP12: 0.01481671 | AQ12: 0.0084978663 | AR12: 0.004785211 | AS12: 0.015406587 | AT12: 0.0066020123 | AU12: 0.015831692 | AV12: 0.006908721 | AW12: 0.0066020123 | AX12: 0 | AY12: 0.0092467816 | AZ12: 0.0042289367 | BA12: 0.01481671 | BB12: 0.0078023247 | BC12: 0.0023730755 | BD12: 0.0092467816 | BE12: 0.0045883703 | BF12: 0 | BG12: 0.0092817965 | BH12: 0.0046586047 | BI12: 0.0042289367 | BJ12: 0.010122675 | BK12: 0.0042289367 | BL12: 0 | BM12: 0.0042289367 | BN12: 0.0042289367 | BO12: 0.012025835 | BP12: 0.0045883703 | BQ12: 0 | BR12: 0.006908721 | BS12: 0.0042289367 | BT12: 0.0039457118 | BU12: 0.0042289367
A13: 10 | B13: V2_16 | C13: =VLOOKUP(B13,Name!$B$7:$C$98,2, FALSE) -> H2-21 | D13: HCOM2 | E13: Expanded | F13: 3 | G13: 0 | H13: 3 | I13: 0 | J13: 0 | K13: 1 | L13: 0 | M13: 0 | N13: 0 | O13: 2 | P13: 0 | Q13: 0 | R13: 0.33773839 | S13: 2.1637362 | T13: 1.2640353 | U13: 0.86652534 | V13: 1.3763398 | W13: 2.5924451 | X13: 1.8512089 | Y13: 2.087932 | Z13: 0.48905747 | AA13: 1.7716854 | AB13: 0.21623907 | AC13: 2.0900454 | AD13: 0.33099713 | AE13: 0.012069883 | AF13: 0.77229334 | AG13: 0.85381409 | AH13: 0.67736359 | AI13: 0.011314318 | AJ13: 1.5405569 | AK13: 0.0023478368 | AL13: 0.0023478368 | AM13: 0.014302346 | AN13: 0.0072946234 | AO13: 0.016586687 | AP13: 0.0070977451 | AQ13: 0.004721714 | AR13: 0.011314318 | AS13: 0.021400091 | AT13: 0.004721714 | AU13: 0.0094353966 | AV13: 0.0065390585 | AW13: 0.004721714 | AX13: 0.012069883 | AY13: 0.014785002 | AZ13: 0.0094889421 | BA13: 0.01450231 | BB13: 0.0070977451 | BC13: 0.0056473375 | BD13: 0.0095002358 | BE13: 0.0070977451 | BF13: 0.0065470899 | BG13: 0.0047136825 | BH13: 0.0065390585 | BI13: 0.004721714 | BJ13: 0.0047136825 | BK13: 0.01108288 | BL13: 0.014152951 | BM13: 0.024633335 | BN13: 0.014152951 | BO13: 0.014526206 | BP13: 0.008109306 | BQ13: 0.01108288 | BR13: 0.008109306 | BS13: 0.011596627 | BT13: 0.0094889421 | BU13: 0.0038219615
A14: 11 | B14: V1_28 | C14: =VLOOKUP(B14,Name!$B$7:$C$98,2, FALSE) -> H1-38 | D14: HCOM1 | E14: Expanded | F14: 9 | G14: 5 | H14: 4 | I14: 0 | J14: 0 | K14: 3 | L14: 0 | M14: 0 | N14: 0 | O14: 5 | P14: 1 | Q14: 0 | R14: 0.46201496 | S14: 1.4124267 | T14: 1.242588 | U14: 1.0432481 | V14: 1.0708675 | W14: 2.3926365 | X14: 1.7955453 | Y14: 1.9750225 | Z14: 0.41136722 | AA14: 1.8773739 | AB14: 0.12988611 | AC14: 1.6771277 | AD14: 0.73171651 | AE14: 0.63597563 | AF14: 1.5033517 | AG14: 0.4101721 | AH14: 0.29133038 | AI14: 0.01116753 | AJ14: 1.684635 | AK14: 0.004787304 | AL14: 0.012136232 | AM14: 0.015915165 | AN14: 0.016381418 | AO14: 0.01267874 | AP14: 0.012446004 | AQ14: 0.0092610835 | AR14: 0.0082938829 | AS14: 0.015124987 | AT14: 0 | AU14: 0.012126325 | AV14: 0.012126325 | AW14: 0.0057010831 | AX14: 0.013125147 | AY14: 0.010253751 | AZ14: 0.011594114 | BA14: 0.018806407 | BB14: 0.013453176 | BC14: 0.01116753 | BD14: 0.01100693 | BE14: 0.0085819405 | BF14: 0.0054664469 | BG14: 0.0023832967 | BH14: 0.010039729 | BI14: 0.017060561 | BJ14: 0.018806407 | BK14: 0.020521026 | BL14: 0.015407685 | BM14: 0.015407685 | BN14: 0.015407685 | BO14: 0.010390386 | BP14: 0.024713118 | BQ14: 0.015407685 | BR14: 0.014728542 | BS14: 0.0099412383 | BT14: 0.015407685 | BU14: 0.0099412383
A15: 12 | B15: V1_32 | C15: =VLOOKUP(B15,Name!$B$7:$C$98,2, FALSE) -> H1-24 | D15: HCOM1 | E15: Expanded | F15: 3 | G15: 0 | H15: 3 | I15: 0 | J15: 0 | K15: 2 | L15: 0 | M15: 0 | N15: 0 | O15: 1 | P15: 0 | Q15: 0 | R15: 1.0462252 | S15: 2.1251264 | T15: 1.4843366 | U15: 1.2729966 | V15: 1.0729896 | W15: 3.1630715 | X15: 2.6301427 | Y15: 2.4140421 | Z15: 0.49255102 | AA15: 2.335393 | AB15: 0.15762352 | AC15: 2.1454796 | AD15: 0.64171487 | AE15: 0.62615971 | AF15: 1.7463406 | AG15: 0.46485368 | AH15: 0.35417895 | AI15: 0.0083567322 | AJ15: 1.6625576 | AK15: 0.003612887 | AL15: 0.0060087813 | AM15: 0.0076350493 | AN15: 0.016346135 | AO15: 0.012256976 | AP15: 0.026364216 | AQ15: 0.015549879 | AR15: 0.005239155 | AS15: 0.0079589697 | AT15: 0.0037313734 | AU15: 0.012256976 | AV15: 0.0063676888 | AW15: 0.0037313734 | AX15: 0.011551905 | AY15: 0.010099062 | AZ15: 0.0078205318 | BA15: 0.018522094 | BB15: 0.014188221 | BC15: 0.005239155 | BD15: 0.012048128 | BE15: 0.010249149 | BF15: 0.0015077816 | BG15: 0.0021051054 | BH15: 0.0078754704 | BI15: 0.015876714 | BJ15: 0.020344109 | BK15: 0.0039036759 | BL15: 0.011931576 | BM15: 0.0076350493 | BN15: 0.0078801822 | BO15: 0.019791367 | BP15: 0.010271365 | BQ15: 0.0076350493 | BR15: 0.010271365 | BS15: 0.0076350493 | BT15: 0.011611556 | BU15: 0.0076350493
A16: 13 | B16: V1_50 | C16: =VLOOKUP(B16,Name!$B$7:$C$98,2, FALSE) -> H1-09 | D16: HCOM1 | E16: Single | F16: 1 | G16: 0 | H16: 1 | I16: 0 | J16: 0 | K16: 0 | L16: 0 | M16: 0 | N16: 0 | O16: 0 | P16: 1 | Q16: 0 | R16: 0.19044736 | S16: 0.73331583 | T16: 0.82558741 | U16: 0.13411161 | V16: 1.0321524 | W16: 2.6370622 | X16: 1.8259473 | Y16: 0.81775242 | Z16: 0.020369133 | AA16: 0.76534093 | AB16: 0.29065485 | AC16: 0.90220258 | AD16: 0.25419221 | AE16: 0.29334162 | AF16: 0.13457199 | AG16: 0.14317439 | AH16: 1.109992 | AI16: 0 | AJ16: 0 | AK16: 0.0074209578 | AL16: 0.0059131762 | AM16: 0 | AN16: 0.011906704 | AO16: 0.015282676 | AP16: 0.0098829924 | AQ16: 0.0032981275 | AR16: 0.0030491887 | AS16: 0.015282676 | AT16: 0.0032981275 | AU16: 0.015282676 | AV16: 0.011450572 | AW16: 0.0048059091 | AX16: 0.0032981275 | AY16: 0.0099427901 | AZ16: 0 | BA16: 0.016123179 | BB16: 0.0099427901 | BC16: 0 | BD16: 0.016123179 | BE16: 0.0079190788 | BF16: 0 | BG16: 0.0079190788 | BH16: 0.011984548 | BI16: 0 | BJ16: 0.014044596 | BK16: 0 | BL16: 0 | BM16: 0.0032981275 | BN16: 0 | BO16: 0 | BP16: 0.0099427901 | BQ16: 0 | BR16: 0.011984548 | BS16: 0 | BT16: 0 | BU16: 0.0032981275
... A39: 36 | B39: V2_05 | C39: =VLOOKUP(B39,Name!$B$7:$C$98,2, FALSE) -> H2-34 | D39: HCOM2 | E39: Expanded | F39: 8 | G39: 1 | H39: 7 | I39: 0 | J39: 1 | K39: 0 | L39: 0 | M39: 2 | N39: 3 | O39: 0 | P39: 0 | Q39: 2 | R39: 0.004649419 | S39: 0.0023125108 | T39: 0.004649419 | U39: 0.0023125108 | V39: 0.004649419 | W39: 0.010346626 | X39: 0.0061488025 | Y39: 0.0023125108 | Z39: 0.0023125108 | AA39: 0.0023125108 | AB39: 0.0023125108 | AC39: 0.0023125108 | AD39: 0.0082376632 | AE39: 0.0023125108 | AF39: 0.0023125108 | AG39: 0.0023125108 | AH39: 0.0023125108 | AI39: 0.0046855863 | AJ39: 0.0079387147 | AK39: 0.0044033245 | AL39: 0.0082376632 | AM39: 0.0056018065 | AN39: 0.011600652 | AO39: 0.012659137 | AP39: 0.011600652 | AQ39: 0.004649419 | AR39: 0.0046855863 | AS39: 0.008729177 | AT39: 0.0070224945 | AU39: 0.012887082 | AV39: 0.014849058 | AW39: 0.0046855863 | AX39: 0.0023125108 | AY39: 0.014788493 | AZ39: 0.0023125108 | BA39: 0.0061488025 | BB39: 0.0082376632 | BC39: 0.0023125108 | BD39: 0.010346626 | BE39: 0.010346626 | BF39: 0.0046855863 | BG39: 0.002030249 | BH39: 0.0082376632 | BI39: 0.004649419 | BJ39: 0.017989019 | BK39: 0.0056018065 | BL39: 0.0056018065 | BM39: 0.0056018065 | BN39: 0.0079387147 | BO39: 0.0089469305 | BP39: 0.0061488025 | BQ39: 0.0089469305 | BR39: 0.0082376632 | BS39: 0.0023125108 | BT39: 0.0032892958 | BU39: 0.078302115

Sheet Sheet2
AK1: 24 | AL1: 27 | AM1: 29 | AN1: 31 | AO1: 32 | AP1: 34 | AQ1: 35 | AR1: 37 | AS1: 38 | AT1: 40 | AU1: 41 | AV1: 43 | AW1: 45 | AX1: 50 | AY1: 53 | AZ1: 56 | BA1: 62 | BB1: 78 | BC1: 94 | BD1: -1 | BE1: 0 | BF1: 4 | BG1: 5 | BH1: 6 | BI1: 12 | BJ1: 20 | BK1: 22 | BL1: 23 | BM1: 26 | BN1: 30 | BO1: 33 | BP1: 36 | BQ1: 39 | BR1: 42 | BS1: 44 | BT1: 46 | BU1: 52 | BV1: 66 | BW1: 68 | BX1: 69 | BY1: 74 | BZ1: 76 | CA1: 77 | CB1: 86 | CC1: 100 | CD1: 104 | CE1: 106 | CF1: 107 | CG1: 109 | CH1: 114 | CI1: 121 | CJ1: 123 | CK1: 124 | CL1: 125 | CM1: 127 | CN1: 131
AK2: Coprococcus eutactus ATCC 27759 | AL2: Eubacterium rectale ATCC 33656 | AM2: Tyzzerella nexilis DSM 1787 | AN2: Clostridium sp. L2-50 | AO2: Clostridium sp. M62/1 | AP2: Clostridium bolteae ATCC BAA-613 | AQ2: Clostridium hathewayi DSM 13479 | AR2: Dorea formicigenerans ATCC 27755 | AS2: Dorea longicatena DSM 13814 | AT2: Blautia hansenii DSM 20583 | AU2: Marvinbryantia formatexigens DSM 14469 (Bryantella formatexigens) | AV2: Ruminococcus torques ATCC 27756 | AW2: Subdoligranulum variabile DSM 15176 | AX2: Eubacterium ventriosum ATCC 27560 DSM 3988 | AY2: Anaerobutyricum hallii DSM 3353 (Eubacterium hallii) | AZ2: Ruminococcus lactaris ATCC 29176 | BA2: Holdemanella biformis DSM 3989 | BB2: Collinsella stercoris DSM 13279 | BC2: Solobacterium moorei DSM 22971 | BD2: Chaw | BE2: GF pellet | BF2: Bacteroides coprophilus DSM 18228 | BG2: Bacteroides dorei 5_1_36/D4 (HM 29) | BH2: Bacteroides eggerthii DSM 20697 | BI2: Bacteroides sp. 3_1_19 | BJ2: Bacteroides plebeius DSM 17135 | BK2: Bacteroides coprocola DSM 17136 | BL2: Bacteroides stercoris ATCC 43183 DSMZ 19555 | BM2: Ruminococcus gnavus ATCC 29149 | BN2: Clostridium scindens ATCC 35704 | BO2: Clostridium asparagiforme DSM 15981 | BP2: Clostridium leptum DSM 753 | BQ2: Coprococcus comes ATCC 27758 | BR2: Butyrivibrio crossotus DSM 2876 | BS2: Parabacteroides merdae DSMZ 19495 (also ATCC 43184) | BT2: Parabacteroides johnsonii DSM 18315 | BU2: Parabacteroides sp. D13 | BV2: Eubacterium siraeum DSM 15702 | BW2: Anaerostipes caccae DSM 14662 | BX2: Bacteroides cellulosilyticus DSM 14838 | BY2: Acidaminococcus fermentans DSM 20731 | BZ2: Ethanoligenens harbinense YUAN-3 DSMZ 18485 | CA2: Veillonella dispar ATCC 17748 | CB2: Veillonella sp. 6_1_27 HM 49 | CC2: Clostridium sporogenes ATCC 15579 | CD2: Ruminococcus albus strain 8 | CE2: Ruminococcus bromii ATCC | CF2: Veillonella sp. 3_1_44 HM 64 | CG2: Megasphaera DSMZ 102144 | CH2: Blautia sp. KLE 1732 (HM 1032) | CI2: Bilophila wadsworthia ATCC 49260 | CJ2: Subdoligranulum sp. 4_3_54A2FAA | CK2: Alistipes senegalensis JC50/DSM 25460 | CL2: Blautia wexlerae DSM 19850 | CM2: Intestinimonas butyriciproducens DSM 26588 | CN2: Burkholderiales bacterium 1_1_47
H8: pTreg
H9: tTreg
H10: Th1
H11: Th2
H12: Th17
H13: Fr4 Th
H14: Other Effector Th
H15: Memory
D19: TCR | E19: Community | F19: Type | G19: Tissue | H19: Total cells | I19: T cell subset | CR19: TCR | CS19: pTreg | CT19: tTreg | CU19: Th1 | CV19: Th2 | CW19: Th17 | CX19: Fr4 Th | CY19: Other Effector Th | CZ19: Memory
